package coreLab.core.lesexceptions;

public class Main {

	public static void main(String[] args) {

		try {

			int dividByZero = 5 / 1;
			System.out.println("resultat de la division  " + dividByZero);
			System.out.println("instruction suite Ã  la division");

		} catch (ArithmeticException e) {
			e.printStackTrace();
		}finally {
			System.out.println("instruction dans le finally...");
		}
		System.out.println("suite du programme...");
	}

}
